[2025-10-04T23:59:11.441+0000] {local_task_job_runner.py:123} INFO - ::group::Pre task execution logs
[2025-10-04T23:59:11.493+0000] {taskinstance.py:2612} INFO - Dependencies all met for dep_context=non-requeueable deps ti=<TaskInstance: forest_cover_mlops_pipeline.store_batch_in_postgres manual__2025-10-04T23:57:04.275654+00:00 [queued]>
[2025-10-04T23:59:11.515+0000] {taskinstance.py:2612} INFO - Dependencies all met for dep_context=requeueable deps ti=<TaskInstance: forest_cover_mlops_pipeline.store_batch_in_postgres manual__2025-10-04T23:57:04.275654+00:00 [queued]>
[2025-10-04T23:59:11.516+0000] {taskinstance.py:2865} INFO - Starting attempt 2 of 3
[2025-10-04T23:59:11.548+0000] {taskinstance.py:2888} INFO - Executing <Task(_PythonDecoratedOperator): store_batch_in_postgres> on 2025-10-04 23:57:04.275654+00:00
[2025-10-04T23:59:11.565+0000] {standard_task_runner.py:72} INFO - Started process 342 to run task
[2025-10-04T23:59:11.572+0000] {standard_task_runner.py:104} INFO - Running: ['airflow', 'tasks', 'run', 'forest_cover_mlops_pipeline', 'store_batch_in_postgres', 'manual__2025-10-04T23:57:04.275654+00:00', '--job-id', '4', '--raw', '--subdir', 'DAGS_FOLDER/forest_cover_dag.py', '--cfg-path', '/home/airflow/tmp/tmpi1px9q82']
[2025-10-04T23:59:11.577+0000] {standard_task_runner.py:105} INFO - Job 4: Subtask store_batch_in_postgres
[2025-10-04T23:59:11.713+0000] {task_command.py:467} INFO - Running <TaskInstance: forest_cover_mlops_pipeline.store_batch_in_postgres manual__2025-10-04T23:57:04.275654+00:00 [running]> on host 00987e5ebe37
[2025-10-04T23:59:11.936+0000] {taskinstance.py:3131} INFO - Exporting env vars: AIRFLOW_CTX_DAG_OWNER='mlops-team' AIRFLOW_CTX_DAG_ID='forest_cover_mlops_pipeline' AIRFLOW_CTX_TASK_ID='store_batch_in_postgres' AIRFLOW_CTX_EXECUTION_DATE='2025-10-04T23:57:04.275654+00:00' AIRFLOW_CTX_TRY_NUMBER='2' AIRFLOW_CTX_DAG_RUN_ID='manual__2025-10-04T23:57:04.275654+00:00'
[2025-10-04T23:59:11.937+0000] {taskinstance.py:731} INFO - ::endgroup::
[2025-10-04T23:59:11.969+0000] {logging_mixin.py:190} INFO - âœ— Error al almacenar en PostgreSQL: relation "data_batches" does not exist
LINE 2:                 INSERT INTO data_batches 
                                    ^
[2025-10-04T23:59:11.970+0000] {taskinstance.py:3310} ERROR - Task failed with exception
Traceback (most recent call last):
  File "/home/airflow/.local/lib/python3.11/site-packages/airflow/models/taskinstance.py", line 767, in _execute_task
    result = _execute_callable(context=context, **execute_callable_kwargs)
             ^^^^^^^^^^^^^^^^^^^^^^^^^^^^^^^^^^^^^^^^^^^^^^^^^^^^^^^^^^^^^
  File "/home/airflow/.local/lib/python3.11/site-packages/airflow/models/taskinstance.py", line 733, in _execute_callable
    return ExecutionCallableRunner(
           ^^^^^^^^^^^^^^^^^^^^^^^^
  File "/home/airflow/.local/lib/python3.11/site-packages/airflow/utils/operator_helpers.py", line 252, in run
    return self.func(*args, **kwargs)
           ^^^^^^^^^^^^^^^^^^^^^^^^^^
  File "/home/airflow/.local/lib/python3.11/site-packages/airflow/models/baseoperator.py", line 406, in wrapper
    return func(self, *args, **kwargs)
           ^^^^^^^^^^^^^^^^^^^^^^^^^^^
  File "/home/airflow/.local/lib/python3.11/site-packages/airflow/decorators/base.py", line 266, in execute
    return_value = super().execute(context)
                   ^^^^^^^^^^^^^^^^^^^^^^^^
  File "/home/airflow/.local/lib/python3.11/site-packages/airflow/models/baseoperator.py", line 406, in wrapper
    return func(self, *args, **kwargs)
           ^^^^^^^^^^^^^^^^^^^^^^^^^^^
  File "/home/airflow/.local/lib/python3.11/site-packages/airflow/operators/python.py", line 238, in execute
    return_value = self.execute_callable()
                   ^^^^^^^^^^^^^^^^^^^^^^^
  File "/home/airflow/.local/lib/python3.11/site-packages/airflow/operators/python.py", line 256, in execute_callable
    return runner.run(*self.op_args, **self.op_kwargs)
           ^^^^^^^^^^^^^^^^^^^^^^^^^^^^^^^^^^^^^^^^^^^
  File "/home/airflow/.local/lib/python3.11/site-packages/airflow/utils/operator_helpers.py", line 252, in run
    return self.func(*args, **kwargs)
           ^^^^^^^^^^^^^^^^^^^^^^^^^^
  File "/opt/airflow/dags/forest_cover_dag.py", line 150, in store_batch_in_postgres
    cursor.execute(insert_query, (
psycopg2.errors.UndefinedTable: relation "data_batches" does not exist
LINE 2:                 INSERT INTO data_batches 
                                    ^

[2025-10-04T23:59:12.016+0000] {taskinstance.py:1225} INFO - Marking task as UP_FOR_RETRY. dag_id=forest_cover_mlops_pipeline, task_id=store_batch_in_postgres, run_id=manual__2025-10-04T23:57:04.275654+00:00, execution_date=20251004T235704, start_date=20251004T235911, end_date=20251004T235912
[2025-10-04T23:59:12.044+0000] {taskinstance.py:340} INFO - ::group::Post task execution logs
[2025-10-04T23:59:12.045+0000] {standard_task_runner.py:124} ERROR - Failed to execute job 4 for task store_batch_in_postgres (relation "data_batches" does not exist
LINE 2:                 INSERT INTO data_batches 
                                    ^
; 342)
Traceback (most recent call last):
  File "/home/airflow/.local/lib/python3.11/site-packages/airflow/task/task_runner/standard_task_runner.py", line 117, in _start_by_fork
    ret = args.func(args, dag=self.dag)
          ^^^^^^^^^^^^^^^^^^^^^^^^^^^^^
  File "/home/airflow/.local/lib/python3.11/site-packages/airflow/cli/cli_config.py", line 49, in command
    return func(*args, **kwargs)
           ^^^^^^^^^^^^^^^^^^^^^
  File "/home/airflow/.local/lib/python3.11/site-packages/airflow/utils/cli.py", line 115, in wrapper
    return f(*args, **kwargs)
           ^^^^^^^^^^^^^^^^^^
  File "/home/airflow/.local/lib/python3.11/site-packages/airflow/cli/commands/task_command.py", line 483, in task_run
    task_return_code = _run_task_by_selected_method(args, _dag, ti)
                       ^^^^^^^^^^^^^^^^^^^^^^^^^^^^^^^^^^^^^^^^^^^^
  File "/home/airflow/.local/lib/python3.11/site-packages/airflow/cli/commands/task_command.py", line 256, in _run_task_by_selected_method
    return _run_raw_task(args, ti)
           ^^^^^^^^^^^^^^^^^^^^^^^
  File "/home/airflow/.local/lib/python3.11/site-packages/airflow/cli/commands/task_command.py", line 341, in _run_raw_task
    return ti._run_raw_task(
           ^^^^^^^^^^^^^^^^^
  File "/home/airflow/.local/lib/python3.11/site-packages/airflow/utils/session.py", line 97, in wrapper
    return func(*args, session=session, **kwargs)
           ^^^^^^^^^^^^^^^^^^^^^^^^^^^^^^^^^^^^^^
  File "/home/airflow/.local/lib/python3.11/site-packages/airflow/models/taskinstance.py", line 3004, in _run_raw_task
    return _run_raw_task(
           ^^^^^^^^^^^^^^
  File "/home/airflow/.local/lib/python3.11/site-packages/airflow/models/taskinstance.py", line 273, in _run_raw_task
    TaskInstance._execute_task_with_callbacks(
  File "/home/airflow/.local/lib/python3.11/site-packages/airflow/models/taskinstance.py", line 3158, in _execute_task_with_callbacks
    result = self._execute_task(context, task_orig)
             ^^^^^^^^^^^^^^^^^^^^^^^^^^^^^^^^^^^^^^
  File "/home/airflow/.local/lib/python3.11/site-packages/airflow/models/taskinstance.py", line 3182, in _execute_task
    return _execute_task(self, context, task_orig)
           ^^^^^^^^^^^^^^^^^^^^^^^^^^^^^^^^^^^^^^^
  File "/home/airflow/.local/lib/python3.11/site-packages/airflow/models/taskinstance.py", line 767, in _execute_task
    result = _execute_callable(context=context, **execute_callable_kwargs)
             ^^^^^^^^^^^^^^^^^^^^^^^^^^^^^^^^^^^^^^^^^^^^^^^^^^^^^^^^^^^^^
  File "/home/airflow/.local/lib/python3.11/site-packages/airflow/models/taskinstance.py", line 733, in _execute_callable
    return ExecutionCallableRunner(
           ^^^^^^^^^^^^^^^^^^^^^^^^
  File "/home/airflow/.local/lib/python3.11/site-packages/airflow/utils/operator_helpers.py", line 252, in run
    return self.func(*args, **kwargs)
           ^^^^^^^^^^^^^^^^^^^^^^^^^^
  File "/home/airflow/.local/lib/python3.11/site-packages/airflow/models/baseoperator.py", line 406, in wrapper
    return func(self, *args, **kwargs)
           ^^^^^^^^^^^^^^^^^^^^^^^^^^^
  File "/home/airflow/.local/lib/python3.11/site-packages/airflow/decorators/base.py", line 266, in execute
    return_value = super().execute(context)
                   ^^^^^^^^^^^^^^^^^^^^^^^^
  File "/home/airflow/.local/lib/python3.11/site-packages/airflow/models/baseoperator.py", line 406, in wrapper
    return func(self, *args, **kwargs)
           ^^^^^^^^^^^^^^^^^^^^^^^^^^^
  File "/home/airflow/.local/lib/python3.11/site-packages/airflow/operators/python.py", line 238, in execute
    return_value = self.execute_callable()
                   ^^^^^^^^^^^^^^^^^^^^^^^
  File "/home/airflow/.local/lib/python3.11/site-packages/airflow/operators/python.py", line 256, in execute_callable
    return runner.run(*self.op_args, **self.op_kwargs)
           ^^^^^^^^^^^^^^^^^^^^^^^^^^^^^^^^^^^^^^^^^^^
  File "/home/airflow/.local/lib/python3.11/site-packages/airflow/utils/operator_helpers.py", line 252, in run
    return self.func(*args, **kwargs)
           ^^^^^^^^^^^^^^^^^^^^^^^^^^
  File "/opt/airflow/dags/forest_cover_dag.py", line 150, in store_batch_in_postgres
    cursor.execute(insert_query, (
psycopg2.errors.UndefinedTable: relation "data_batches" does not exist
LINE 2:                 INSERT INTO data_batches 
                                    ^

[2025-10-04T23:59:12.067+0000] {local_task_job_runner.py:266} INFO - Task exited with return code 1
[2025-10-04T23:59:12.087+0000] {taskinstance.py:3900} INFO - 0 downstream tasks scheduled from follow-on schedule check
[2025-10-04T23:59:12.089+0000] {local_task_job_runner.py:245} INFO - ::endgroup::
