[2025-10-05T01:45:39.580+0000] {local_task_job_runner.py:123} INFO - ::group::Pre task execution logs
[2025-10-05T01:45:39.592+0000] {taskinstance.py:2612} INFO - Dependencies all met for dep_context=non-requeueable deps ti=<TaskInstance: forest_cover_mlops_pipeline.train_and_log_models manual__2025-10-05T01:43:10.960481+00:00 [queued]>
[2025-10-05T01:45:39.596+0000] {taskinstance.py:2612} INFO - Dependencies all met for dep_context=requeueable deps ti=<TaskInstance: forest_cover_mlops_pipeline.train_and_log_models manual__2025-10-05T01:43:10.960481+00:00 [queued]>
[2025-10-05T01:45:39.597+0000] {taskinstance.py:2865} INFO - Starting attempt 2 of 3
[2025-10-05T01:45:39.603+0000] {taskinstance.py:2888} INFO - Executing <Task(_PythonDecoratedOperator): train_and_log_models> on 2025-10-05 01:43:10.960481+00:00
[2025-10-05T01:45:39.608+0000] {standard_task_runner.py:72} INFO - Started process 1258 to run task
[2025-10-05T01:45:39.611+0000] {standard_task_runner.py:104} INFO - Running: ['airflow', 'tasks', 'run', 'forest_cover_mlops_pipeline', 'train_and_log_models', 'manual__2025-10-05T01:43:10.960481+00:00', '--job-id', '14', '--raw', '--subdir', 'DAGS_FOLDER/forest_cover_dag.py', '--cfg-path', '/home/airflow/tmp/tmpbx1sgrey']
[2025-10-05T01:45:39.612+0000] {standard_task_runner.py:105} INFO - Job 14: Subtask train_and_log_models
[2025-10-05T01:45:39.709+0000] {task_command.py:467} INFO - Running <TaskInstance: forest_cover_mlops_pipeline.train_and_log_models manual__2025-10-05T01:43:10.960481+00:00 [running]> on host 251551b582e0
[2025-10-05T01:45:39.924+0000] {taskinstance.py:3131} INFO - Exporting env vars: AIRFLOW_CTX_DAG_OWNER='mlops-team-5' AIRFLOW_CTX_DAG_ID='forest_cover_mlops_pipeline' AIRFLOW_CTX_TASK_ID='train_and_log_models' AIRFLOW_CTX_EXECUTION_DATE='2025-10-05T01:43:10.960481+00:00' AIRFLOW_CTX_TRY_NUMBER='2' AIRFLOW_CTX_DAG_RUN_ID='manual__2025-10-05T01:43:10.960481+00:00'
[2025-10-05T01:45:39.925+0000] {taskinstance.py:731} INFO - ::endgroup::
[2025-10-05T01:45:40.181+0000] {logging_mixin.py:190} INFO - Entrenando 3 modelos con GridSearchCV...
[2025-10-05T01:45:40.182+0000] {logging_mixin.py:190} INFO - 
==================================================
[2025-10-05T01:45:40.182+0000] {logging_mixin.py:190} INFO - Modelo: RandomForest
[2025-10-05T01:45:40.182+0000] {logging_mixin.py:190} INFO - ==================================================
[2025-10-05T01:45:40.200+0000] {logging_mixin.py:190} WARNING - 2025/10/05 01:45:40 WARNING mlflow.utils.git_utils: Failed to import Git (the Git executable is probably not on your PATH), so Git SHA is not available. Error: Failed to initialize: Bad git executable.
The git executable must be specified in one of the following ways:
    - be included in your $PATH
    - be set via $GIT_PYTHON_GIT_EXECUTABLE
    - explicitly set via git.refresh(<full-path-to-git-executable>)

All git commands will error until this is rectified.

This initial message can be silenced or aggravated in the future by setting the
$GIT_PYTHON_REFRESH environment variable. Use one of the following values:
    - quiet|q|silence|s|silent|none|n|0: for no message or exception
    - warn|w|warning|log|l|1: for a warning message (logging level CRITICAL, displayed by default)
    - error|e|exception|raise|r|2: for a raised exception

Example:
    export GIT_PYTHON_REFRESH=quiet
[2025-10-05T01:45:40.256+0000] {warnings.py:110} WARNING - /home/airflow/.local/lib/python3.11/site-packages/joblib/parallel.py:1379: UserWarning: Loky-backed parallel loops cannot be called in a multiprocessing, setting n_jobs=1
  n_jobs = self._backend.configure(

[2025-10-05T01:45:40.256+0000] {logging_mixin.py:190} INFO - Fitting 3 folds for each of 12 candidates, totalling 36 fits
[2025-10-05T01:45:55.780+0000] {logging_mixin.py:190} INFO -   Mejores par√°metros: {'classifier__max_depth': 20, 'classifier__min_samples_split': 2, 'classifier__n_estimators': 100}
[2025-10-05T01:45:57.610+0000] {logging_mixin.py:190} INFO -   Train Accuracy: 1.0000
[2025-10-05T01:45:57.610+0000] {logging_mixin.py:190} INFO -   Test Accuracy: 0.9303
[2025-10-05T01:45:57.610+0000] {logging_mixin.py:190} INFO -   Test F1 (weighted): 0.9298
[2025-10-05T01:45:57.610+0000] {logging_mixin.py:190} INFO -   CV Score: 0.9089 (+/- 0.0022)
[2025-10-05T01:45:59.760+0000] {logging_mixin.py:190} WARNING - 2025/10/05 01:45:59 WARNING mlflow.models.model: Model logged without a signature and input example. Please set `input_example` parameter when logging the model to auto infer the model signature.
[2025-10-05T01:45:59.811+0000] {credentials.py:1147} INFO - Found credentials in environment variables.
[2025-10-05T01:45:59.866+0000] {logging_mixin.py:190} WARNING - 2025/10/05 01:45:59 INFO mlflow.tracking._tracking_service.client: üèÉ View run RandomForest_batch_2 at: http://mlflow:5000/#/experiments/1/runs/6933ee14454a41c2a898bcc270bd1967.
[2025-10-05T01:45:59.866+0000] {logging_mixin.py:190} WARNING - 2025/10/05 01:45:59 INFO mlflow.tracking._tracking_service.client: üß™ View experiment at: http://mlflow:5000/#/experiments/1.
[2025-10-05T01:45:59.878+0000] {logging_mixin.py:190} INFO - ‚úó Error en entrenamiento: Failed to upload /home/airflow/tmp/tmph42_nfsm/model/model.pkl to mlflows3/artifacts/1/6933ee14454a41c2a898bcc270bd1967/artifacts/model_randomforest/model.pkl: An error occurred (NoSuchBucket) when calling the CreateMultipartUpload operation: The specified bucket does not exist
[2025-10-05T01:45:59.878+0000] {taskinstance.py:3310} ERROR - Task failed with exception
Traceback (most recent call last):
  File "/home/airflow/.local/lib/python3.11/site-packages/boto3/s3/transfer.py", line 372, in upload_file
    future.result()
  File "/home/airflow/.local/lib/python3.11/site-packages/s3transfer/futures.py", line 103, in result
    return self._coordinator.result()
           ^^^^^^^^^^^^^^^^^^^^^^^^^^
  File "/home/airflow/.local/lib/python3.11/site-packages/s3transfer/futures.py", line 266, in result
    raise self._exception
  File "/home/airflow/.local/lib/python3.11/site-packages/s3transfer/tasks.py", line 139, in __call__
    return self._execute_main(kwargs)
           ^^^^^^^^^^^^^^^^^^^^^^^^^^
  File "/home/airflow/.local/lib/python3.11/site-packages/s3transfer/tasks.py", line 162, in _execute_main
    return_value = self._main(**kwargs)
                   ^^^^^^^^^^^^^^^^^^^^
  File "/home/airflow/.local/lib/python3.11/site-packages/s3transfer/tasks.py", line 348, in _main
    response = client.create_multipart_upload(
               ^^^^^^^^^^^^^^^^^^^^^^^^^^^^^^^
  File "/home/airflow/.local/lib/python3.11/site-packages/botocore/client.py", line 569, in _api_call
    return self._make_api_call(operation_name, kwargs)
           ^^^^^^^^^^^^^^^^^^^^^^^^^^^^^^^^^^^^^^^^^^^
  File "/home/airflow/.local/lib/python3.11/site-packages/botocore/client.py", line 1023, in _make_api_call
    raise error_class(parsed_response, operation_name)
botocore.errorfactory.NoSuchBucket: An error occurred (NoSuchBucket) when calling the CreateMultipartUpload operation: The specified bucket does not exist

During handling of the above exception, another exception occurred:

Traceback (most recent call last):
  File "/home/airflow/.local/lib/python3.11/site-packages/airflow/models/taskinstance.py", line 767, in _execute_task
    result = _execute_callable(context=context, **execute_callable_kwargs)
             ^^^^^^^^^^^^^^^^^^^^^^^^^^^^^^^^^^^^^^^^^^^^^^^^^^^^^^^^^^^^^
  File "/home/airflow/.local/lib/python3.11/site-packages/airflow/models/taskinstance.py", line 733, in _execute_callable
    return ExecutionCallableRunner(
           ^^^^^^^^^^^^^^^^^^^^^^^^
  File "/home/airflow/.local/lib/python3.11/site-packages/airflow/utils/operator_helpers.py", line 252, in run
    return self.func(*args, **kwargs)
           ^^^^^^^^^^^^^^^^^^^^^^^^^^
  File "/home/airflow/.local/lib/python3.11/site-packages/airflow/models/baseoperator.py", line 406, in wrapper
    return func(self, *args, **kwargs)
           ^^^^^^^^^^^^^^^^^^^^^^^^^^^
  File "/home/airflow/.local/lib/python3.11/site-packages/airflow/decorators/base.py", line 266, in execute
    return_value = super().execute(context)
                   ^^^^^^^^^^^^^^^^^^^^^^^^
  File "/home/airflow/.local/lib/python3.11/site-packages/airflow/models/baseoperator.py", line 406, in wrapper
    return func(self, *args, **kwargs)
           ^^^^^^^^^^^^^^^^^^^^^^^^^^^
  File "/home/airflow/.local/lib/python3.11/site-packages/airflow/operators/python.py", line 238, in execute
    return_value = self.execute_callable()
                   ^^^^^^^^^^^^^^^^^^^^^^^
  File "/home/airflow/.local/lib/python3.11/site-packages/airflow/operators/python.py", line 256, in execute_callable
    return runner.run(*self.op_args, **self.op_kwargs)
           ^^^^^^^^^^^^^^^^^^^^^^^^^^^^^^^^^^^^^^^^^^^
  File "/home/airflow/.local/lib/python3.11/site-packages/airflow/utils/operator_helpers.py", line 252, in run
    return self.func(*args, **kwargs)
           ^^^^^^^^^^^^^^^^^^^^^^^^^^
  File "/opt/airflow/dags/forest_cover_dag.py", line 460, in train_and_log_models
    mlflow.sklearn.log_model(
  File "/home/airflow/.local/lib/python3.11/site-packages/mlflow/sklearn/__init__.py", line 412, in log_model
    return Model.log(
           ^^^^^^^^^^
  File "/home/airflow/.local/lib/python3.11/site-packages/mlflow/models/model.py", line 743, in log
    mlflow.tracking.fluent.log_artifacts(local_path, mlflow_model.artifact_path, run_id)
  File "/home/airflow/.local/lib/python3.11/site-packages/mlflow/tracking/fluent.py", line 1162, in log_artifacts
    MlflowClient().log_artifacts(run_id, local_dir, artifact_path)
  File "/home/airflow/.local/lib/python3.11/site-packages/mlflow/tracking/client.py", line 1971, in log_artifacts
    self._tracking_client.log_artifacts(run_id, local_dir, artifact_path)
  File "/home/airflow/.local/lib/python3.11/site-packages/mlflow/tracking/_tracking_service/client.py", line 853, in log_artifacts
    self._get_artifact_repo(run_id).log_artifacts(local_dir, artifact_path)
  File "/home/airflow/.local/lib/python3.11/site-packages/mlflow/store/artifact/s3_artifact_repo.py", line 194, in log_artifacts
    self._upload_file(
  File "/home/airflow/.local/lib/python3.11/site-packages/mlflow/store/artifact/s3_artifact_repo.py", line 169, in _upload_file
    s3_client.upload_file(Filename=local_file, Bucket=bucket, Key=key, ExtraArgs=extra_args)
  File "/home/airflow/.local/lib/python3.11/site-packages/boto3/s3/inject.py", line 145, in upload_file
    return transfer.upload_file(
           ^^^^^^^^^^^^^^^^^^^^^
  File "/home/airflow/.local/lib/python3.11/site-packages/boto3/s3/transfer.py", line 378, in upload_file
    raise S3UploadFailedError(
boto3.exceptions.S3UploadFailedError: Failed to upload /home/airflow/tmp/tmph42_nfsm/model/model.pkl to mlflows3/artifacts/1/6933ee14454a41c2a898bcc270bd1967/artifacts/model_randomforest/model.pkl: An error occurred (NoSuchBucket) when calling the CreateMultipartUpload operation: The specified bucket does not exist
[2025-10-05T01:45:59.890+0000] {taskinstance.py:1225} INFO - Marking task as UP_FOR_RETRY. dag_id=forest_cover_mlops_pipeline, task_id=train_and_log_models, run_id=manual__2025-10-05T01:43:10.960481+00:00, execution_date=20251005T014310, start_date=20251005T014539, end_date=20251005T014559
[2025-10-05T01:45:59.909+0000] {taskinstance.py:340} INFO - ::group::Post task execution logs
[2025-10-05T01:45:59.909+0000] {standard_task_runner.py:124} ERROR - Failed to execute job 14 for task train_and_log_models (Failed to upload /home/airflow/tmp/tmph42_nfsm/model/model.pkl to mlflows3/artifacts/1/6933ee14454a41c2a898bcc270bd1967/artifacts/model_randomforest/model.pkl: An error occurred (NoSuchBucket) when calling the CreateMultipartUpload operation: The specified bucket does not exist; 1258)
Traceback (most recent call last):
  File "/home/airflow/.local/lib/python3.11/site-packages/boto3/s3/transfer.py", line 372, in upload_file
    future.result()
  File "/home/airflow/.local/lib/python3.11/site-packages/s3transfer/futures.py", line 103, in result
    return self._coordinator.result()
           ^^^^^^^^^^^^^^^^^^^^^^^^^^
  File "/home/airflow/.local/lib/python3.11/site-packages/s3transfer/futures.py", line 266, in result
    raise self._exception
  File "/home/airflow/.local/lib/python3.11/site-packages/s3transfer/tasks.py", line 139, in __call__
    return self._execute_main(kwargs)
           ^^^^^^^^^^^^^^^^^^^^^^^^^^
  File "/home/airflow/.local/lib/python3.11/site-packages/s3transfer/tasks.py", line 162, in _execute_main
    return_value = self._main(**kwargs)
                   ^^^^^^^^^^^^^^^^^^^^
  File "/home/airflow/.local/lib/python3.11/site-packages/s3transfer/tasks.py", line 348, in _main
    response = client.create_multipart_upload(
               ^^^^^^^^^^^^^^^^^^^^^^^^^^^^^^^
  File "/home/airflow/.local/lib/python3.11/site-packages/botocore/client.py", line 569, in _api_call
    return self._make_api_call(operation_name, kwargs)
           ^^^^^^^^^^^^^^^^^^^^^^^^^^^^^^^^^^^^^^^^^^^
  File "/home/airflow/.local/lib/python3.11/site-packages/botocore/client.py", line 1023, in _make_api_call
    raise error_class(parsed_response, operation_name)
botocore.errorfactory.NoSuchBucket: An error occurred (NoSuchBucket) when calling the CreateMultipartUpload operation: The specified bucket does not exist

During handling of the above exception, another exception occurred:

Traceback (most recent call last):
  File "/home/airflow/.local/lib/python3.11/site-packages/airflow/task/task_runner/standard_task_runner.py", line 117, in _start_by_fork
    ret = args.func(args, dag=self.dag)
          ^^^^^^^^^^^^^^^^^^^^^^^^^^^^^
  File "/home/airflow/.local/lib/python3.11/site-packages/airflow/cli/cli_config.py", line 49, in command
    return func(*args, **kwargs)
           ^^^^^^^^^^^^^^^^^^^^^
  File "/home/airflow/.local/lib/python3.11/site-packages/airflow/utils/cli.py", line 115, in wrapper
    return f(*args, **kwargs)
           ^^^^^^^^^^^^^^^^^^
  File "/home/airflow/.local/lib/python3.11/site-packages/airflow/cli/commands/task_command.py", line 483, in task_run
    task_return_code = _run_task_by_selected_method(args, _dag, ti)
                       ^^^^^^^^^^^^^^^^^^^^^^^^^^^^^^^^^^^^^^^^^^^^
  File "/home/airflow/.local/lib/python3.11/site-packages/airflow/cli/commands/task_command.py", line 256, in _run_task_by_selected_method
    return _run_raw_task(args, ti)
           ^^^^^^^^^^^^^^^^^^^^^^^
  File "/home/airflow/.local/lib/python3.11/site-packages/airflow/cli/commands/task_command.py", line 341, in _run_raw_task
    return ti._run_raw_task(
           ^^^^^^^^^^^^^^^^^
  File "/home/airflow/.local/lib/python3.11/site-packages/airflow/utils/session.py", line 97, in wrapper
    return func(*args, session=session, **kwargs)
           ^^^^^^^^^^^^^^^^^^^^^^^^^^^^^^^^^^^^^^
  File "/home/airflow/.local/lib/python3.11/site-packages/airflow/models/taskinstance.py", line 3004, in _run_raw_task
    return _run_raw_task(
           ^^^^^^^^^^^^^^
  File "/home/airflow/.local/lib/python3.11/site-packages/airflow/models/taskinstance.py", line 273, in _run_raw_task
    TaskInstance._execute_task_with_callbacks(
  File "/home/airflow/.local/lib/python3.11/site-packages/airflow/models/taskinstance.py", line 3158, in _execute_task_with_callbacks
    result = self._execute_task(context, task_orig)
             ^^^^^^^^^^^^^^^^^^^^^^^^^^^^^^^^^^^^^^
  File "/home/airflow/.local/lib/python3.11/site-packages/airflow/models/taskinstance.py", line 3182, in _execute_task
    return _execute_task(self, context, task_orig)
           ^^^^^^^^^^^^^^^^^^^^^^^^^^^^^^^^^^^^^^^
  File "/home/airflow/.local/lib/python3.11/site-packages/airflow/models/taskinstance.py", line 767, in _execute_task
    result = _execute_callable(context=context, **execute_callable_kwargs)
             ^^^^^^^^^^^^^^^^^^^^^^^^^^^^^^^^^^^^^^^^^^^^^^^^^^^^^^^^^^^^^
  File "/home/airflow/.local/lib/python3.11/site-packages/airflow/models/taskinstance.py", line 733, in _execute_callable
    return ExecutionCallableRunner(
           ^^^^^^^^^^^^^^^^^^^^^^^^
  File "/home/airflow/.local/lib/python3.11/site-packages/airflow/utils/operator_helpers.py", line 252, in run
    return self.func(*args, **kwargs)
           ^^^^^^^^^^^^^^^^^^^^^^^^^^
  File "/home/airflow/.local/lib/python3.11/site-packages/airflow/models/baseoperator.py", line 406, in wrapper
    return func(self, *args, **kwargs)
           ^^^^^^^^^^^^^^^^^^^^^^^^^^^
  File "/home/airflow/.local/lib/python3.11/site-packages/airflow/decorators/base.py", line 266, in execute
    return_value = super().execute(context)
                   ^^^^^^^^^^^^^^^^^^^^^^^^
  File "/home/airflow/.local/lib/python3.11/site-packages/airflow/models/baseoperator.py", line 406, in wrapper
    return func(self, *args, **kwargs)
           ^^^^^^^^^^^^^^^^^^^^^^^^^^^
  File "/home/airflow/.local/lib/python3.11/site-packages/airflow/operators/python.py", line 238, in execute
    return_value = self.execute_callable()
                   ^^^^^^^^^^^^^^^^^^^^^^^
  File "/home/airflow/.local/lib/python3.11/site-packages/airflow/operators/python.py", line 256, in execute_callable
    return runner.run(*self.op_args, **self.op_kwargs)
           ^^^^^^^^^^^^^^^^^^^^^^^^^^^^^^^^^^^^^^^^^^^
  File "/home/airflow/.local/lib/python3.11/site-packages/airflow/utils/operator_helpers.py", line 252, in run
    return self.func(*args, **kwargs)
           ^^^^^^^^^^^^^^^^^^^^^^^^^^
  File "/opt/airflow/dags/forest_cover_dag.py", line 460, in train_and_log_models
    mlflow.sklearn.log_model(
  File "/home/airflow/.local/lib/python3.11/site-packages/mlflow/sklearn/__init__.py", line 412, in log_model
    return Model.log(
           ^^^^^^^^^^
  File "/home/airflow/.local/lib/python3.11/site-packages/mlflow/models/model.py", line 743, in log
    mlflow.tracking.fluent.log_artifacts(local_path, mlflow_model.artifact_path, run_id)
  File "/home/airflow/.local/lib/python3.11/site-packages/mlflow/tracking/fluent.py", line 1162, in log_artifacts
    MlflowClient().log_artifacts(run_id, local_dir, artifact_path)
  File "/home/airflow/.local/lib/python3.11/site-packages/mlflow/tracking/client.py", line 1971, in log_artifacts
    self._tracking_client.log_artifacts(run_id, local_dir, artifact_path)
  File "/home/airflow/.local/lib/python3.11/site-packages/mlflow/tracking/_tracking_service/client.py", line 853, in log_artifacts
    self._get_artifact_repo(run_id).log_artifacts(local_dir, artifact_path)
  File "/home/airflow/.local/lib/python3.11/site-packages/mlflow/store/artifact/s3_artifact_repo.py", line 194, in log_artifacts
    self._upload_file(
  File "/home/airflow/.local/lib/python3.11/site-packages/mlflow/store/artifact/s3_artifact_repo.py", line 169, in _upload_file
    s3_client.upload_file(Filename=local_file, Bucket=bucket, Key=key, ExtraArgs=extra_args)
  File "/home/airflow/.local/lib/python3.11/site-packages/boto3/s3/inject.py", line 145, in upload_file
    return transfer.upload_file(
           ^^^^^^^^^^^^^^^^^^^^^
  File "/home/airflow/.local/lib/python3.11/site-packages/boto3/s3/transfer.py", line 378, in upload_file
    raise S3UploadFailedError(
boto3.exceptions.S3UploadFailedError: Failed to upload /home/airflow/tmp/tmph42_nfsm/model/model.pkl to mlflows3/artifacts/1/6933ee14454a41c2a898bcc270bd1967/artifacts/model_randomforest/model.pkl: An error occurred (NoSuchBucket) when calling the CreateMultipartUpload operation: The specified bucket does not exist
[2025-10-05T01:45:59.958+0000] {local_task_job_runner.py:266} INFO - Task exited with return code 1
[2025-10-05T01:46:00.004+0000] {taskinstance.py:3900} INFO - 0 downstream tasks scheduled from follow-on schedule check
[2025-10-05T01:46:00.006+0000] {local_task_job_runner.py:245} INFO - ::endgroup::
